Workbook

Sheet Test Cases
A1: Hospital Patient Record and Appointment Management System - Test Cases
A2: Fill the yellow columns (Status, Defect ID, Executed By, Date) during execution. Status values: Not run, Pass, Fail, Blocked. Example: Pass | (blank) | Rohan Agarwal | 20-Oct-2026. IDs follow SRS v1.0 and STP v1.0.
A4: Test Case ID | B4: Module | C4: Requirement ID(s) | D4: Scenario / Steps | E4: Expected Result | F4: Level | G4: Sprint | H4: Priority | I4: Status | J4: Defect ID | K4: Executed By | L4: Date
A5: TC-Auth-01 | B5: Authentication | C5: HMS-F-001, HMS-SR-001 | D5: Register a new patient with valid name, email and password | E5: 201; account stored with bcrypt hash; password not in response | F5: Integration | G5: 1 | H5: High | I5: Pass | K5: Rohan Agarwal | L5: 26-Oct-2026
A6: TC-Auth-02 | B6: Authentication | C6: HMS-F-001 | D6: Register with an email that already exists | E6: 409; no second account created | F6: Integration | G6: 1 | H6: High | I6: Pass | K6: Rohan Agarwal | L6: 26-Oct-2026
A7: TC-Auth-03 | B7: Authentication | C7: HMS-F-001 | D7: Register with invalid email format, or password shorter than 8 characters | E7: 400 with a clear message | F7: Unit | G7: 1 | H7: High | I7: Pass | K7: Rohan Agarwal | L7: 26-Oct-2026
A8: TC-Auth-04 | B8: Authentication | C8: HMS-F-002 | D8: Log in with valid credentials | E8: 200; JWT with user id, role and expiry | F8: Integration | G8: 1 | H8: High | I8: Pass | K8: Rohan Agarwal | L8: 26-Oct-2026
A9: TC-Auth-05 | B9: Authentication | C9: HMS-F-003 | D9: Log in with correct email and wrong password | E9: 401; generic message | F9: Integration | G9: 1 | H9: High | I9: Pass | K9: Rohan Agarwal | L9: 26-Oct-2026
A10: TC-Auth-06 | B10: Authentication | C10: HMS-F-003 | D10: Log in with an unknown email | E10: 401; same message as TC-Auth-05 | F10: Integration | G10: 1 | H10: High | I10: Pass | K10: Rohan Agarwal | L10: 26-Oct-2026
A11: TC-Auth-07 | B11: Authentication | C11: HMS-F-004 | D11: Call a protected endpoint without a token | E11: 401 | F11: Integration | G11: 1 | H11: High | I11: Pass | K11: Rohan Agarwal | L11: 26-Oct-2026
A12: TC-Auth-08 | B12: Authentication | C12: HMS-F-002, HMS-SR-002 | D12: Call a protected endpoint with an expired or tampered token | E12: 401 | F12: Integration | G12: 1 | H12: High | I12: Pass | K12: Rohan Agarwal | L12: 26-Oct-2026
A13: TC-Auth-09 | B13: Authentication | C13: HMS-F-004 | D13: Call an admin route and a doctor-only route with a patient token | E13: 403 | F13: Integration | G13: 1 | H13: High | I13: Pass | K13: Rohan Agarwal | L13: 26-Oct-2026
A14: TC-Auth-10 | B14: Authentication | C14: HMS-F-005 | D14: Log out from the UI, then open a protected page | E14: Token removed; redirected to login | F14: System | G14: 1 | H14: Medium | I14: Not run
A15: TC-Auth-11 | B15: Authentication | C15: HMS-F-056 | D15: Check the server log after one successful and one failed login | E15: Both events logged; no password in the log | F15: Integration | G15: 1 | H15: Medium | I15: Pass | K15: Rohan Agarwal | L15: 26-Oct-2026
A16: TC-Auth-12 | B16: Authentication | C16: HMS-F-006 | D16: A deactivated user tries to log in | E16: Login refused | F16: Integration | G16: 2 | H16: Medium | I16: Pass | K16: Rohan Agarwal | L16: 26-Oct-2026
A17: TC-Pat-01 | B17: Patient Management | C17: HMS-F-010 | D17: Patient views own profile after registering | E17: 200; own data only | F17: Integration | G17: 1 | H17: High | I17: Pass | K17: Rohan Agarwal | L17: 26-Oct-2026
A18: TC-Pat-02 | B18: Patient Management | C18: HMS-F-011 | D18: Patient updates name, phone and address with valid data | E18: 200; confirmation shown; data persisted | F18: Integration | G18: 2 | H18: High | I18: Pass | K18: Rohan Agarwal | L18: 26-Oct-2026
A19: TC-Pat-03 | B19: Patient Management | C19: HMS-F-011 | D19: Send role or id in the update request | E19: Ignored or rejected; role and id unchanged | F19: Integration | G19: 2 | H19: High | I19: Pass | K19: Rohan Agarwal | L19: 26-Oct-2026
A20: TC-Pat-04 | B20: Patient Management | C20: HMS-F-012 | D20: Update with an invalid phone number, then with a future date of birth | E20: 400 with a clear message each time | F20: Unit | G20: 2 | H20: High | I20: Fail | J20: #17 | K20: Rohan Agarwal | L20: 26-Oct-2026
A21: TC-Pat-05 | B21: Patient Management | C21: HMS-F-013 | D21: patient1 requests patient2's data | E21: 403 | F21: Integration | G21: 2 | H21: High | I21: Pass | K21: Rohan Agarwal | L21: 26-Oct-2026
A22: TC-Pat-06 | B22: Patient Management | C22: HMS-F-014 | D22: doctor1 requests a patient with an appointment, then a patient without one | E22: 200 for the first; 403 for the second | F22: Integration | G22: 2 | H22: Medium | I22: Fail | J22: #18 | K22: Rohan Agarwal | L22: 26-Oct-2026
A23: TC-Pat-07 | B23: Patient Management | C23: HMS-F-014 | D23: Administrator requests any patient profile | E23: 200 | F23: Integration | G23: 2 | H23: Medium | I23: Fail | J23: #18 | K23: Rohan Agarwal | L23: 26-Oct-2026
A24: TC-Doc-01 | B24: Doctor Management | C24: HMS-F-020, HMS-F-052 | D24: Administrator creates a doctor account, then the doctor logs in | E24: 201; doctor can log in | F24: Integration | G24: 2 | H24: High | I24: Not run
A25: TC-Doc-02 | B25: Doctor Management | C25: HMS-F-021 | D25: Doctor adds a future availability slot | E25: Slot saved and listed as free | F25: Integration | G25: 1 | H25: High | I25: Pass | K25: Rohan Agarwal | L25: 26-Oct-2026
A26: TC-Doc-03 | B26: Doctor Management | C26: HMS-F-022 | D26: Doctor adds a slot overlapping an existing one | E26: 409; no slot added | F26: Integration | G26: 2 | H26: Medium | I26: Pass | K26: Rohan Agarwal | L26: 26-Oct-2026
A27: TC-Doc-04 | B27: Doctor Management | C27: HMS-F-023 | D27: Patient searches doctors by specialization and by name | E27: Only matching doctors returned | F27: Integration | G27: 1 | H27: High | I27: Pass | K27: Rohan Agarwal | L27: 26-Oct-2026
A28: TC-Doc-05 | B28: Doctor Management | C28: HMS-F-024 | D28: Patient views availability of a doctor that has a booked slot | E28: Booked slot not shown as free | F28: Integration | G28: 1 | H28: High | I28: Pass | K28: Rohan Agarwal | L28: 26-Oct-2026
A29: TC-Doc-06 | B29: Doctor Management | C29: HMS-F-021 | D29: Patient tries to add an availability slot | E29: 403 | F29: Integration | G29: 1 | H29: Medium | I29: Pass | K29: Rohan Agarwal | L29: 26-Oct-2026
A30: TC-Apt-01 | B30: Appointment Management | C30: HMS-F-030 | D30: Patient books a free slot | E30: 201; status Confirmed | F30: Integration | G30: 1 | H30: High | I30: Pass | K30: Rohan Agarwal | L30: 26-Oct-2026
A31: TC-Apt-02 | B31: Appointment Management | C31: HMS-F-031 | D31: Book a slot that already has an active appointment | E31: 409; no second appointment | F31: Integration | G31: 2 | H31: High | I31: Pass | K31: Rohan Agarwal | L31: 26-Oct-2026
A32: TC-Apt-03 | B32: Appointment Management | C32: HMS-F-031 | D32: Two patients send a booking for the same slot at the same time | E32: Exactly one 201 and one 409 | F32: Integration | G32: 2 | H32: High | I32: Not run
A33: TC-Apt-04 | B33: Appointment Management | C33: HMS-F-032 | D33: Book a slot in the past | E33: 400 | F33: Unit | G33: 1 | H33: High | I33: Fail | J33: #19 | K33: Rohan Agarwal | L33: 26-Oct-2026
A34: TC-Apt-05 | B34: Appointment Management | C34: HMS-F-032 | D34: Book with a non-existent doctor id | E34: 404 | F34: Integration | G34: 1 | H34: Medium | I34: Pass | K34: Rohan Agarwal | L34: 26-Oct-2026
A35: TC-Apt-06 | B35: Appointment Management | C35: HMS-F-033 | D35: Patient lists appointments | E35: Own appointments only | F35: Integration | G35: 1 | H35: High | I35: Pass | K35: Rohan Agarwal | L35: 26-Oct-2026
A36: TC-Apt-07 | B36: Appointment Management | C36: HMS-F-033 | D36: Doctor lists appointments | E36: Own appointments only | F36: Integration | G36: 1 | H36: High | I36: Pass | K36: Rohan Agarwal | L36: 26-Oct-2026
A37: TC-Apt-08 | B37: Appointment Management | C37: HMS-F-034 | D37: Reschedule to a free slot | E37: 200; new time saved; old slot free again | F37: Integration | G37: 2 | H37: High | I37: Pass | K37: Rohan Agarwal | L37: 26-Oct-2026
A38: TC-Apt-09 | B38: Appointment Management | C38: HMS-F-034 | D38: Reschedule to a slot that is taken | E38: 409; original appointment unchanged | F38: Integration | G38: 2 | H38: High | I38: Pass | K38: Rohan Agarwal | L38: 26-Oct-2026
A39: TC-Apt-10 | B39: Appointment Management | C39: HMS-F-035 | D39: Cancel an appointment | E39: Status Cancelled; slot can be booked again | F39: Integration | G39: 2 | H39: High | I39: Pass | K39: Rohan Agarwal | L39: 26-Oct-2026
A40: TC-Apt-11 | B40: Appointment Management | C40: HMS-F-036 | D40: patient2 tries to cancel or reschedule patient1's appointment | E40: 403 | F40: Integration | G40: 2 | H40: High | I40: Pass | K40: Rohan Agarwal | L40: 26-Oct-2026
A41: TC-Rec-01 | B41: Medical Record | C41: HMS-F-040 | D41: Doctor creates a record for a patient with an appointment | E41: 201; record stored | F41: Integration | G41: 2 | H41: High | I41: Pass | K41: Rohan Agarwal | L41: 26-Oct-2026
...

Sheet Summary
A1: Test Execution Summary (updates from the Status column)
A3: Sprint | B3: Planned | C3: Pass | D3: Fail | E3: Blocked | F3: Not run | G3: Executed | H3: Pass %
A4: Sprint 1 | B4: =COUNTIFS('Test Cases'!$A$5:$A$82,"<>",'Test Cases'!$G$5:$G$82,1) | C4: =COUNTIFS('Test Cases'!$I$5:$I$82,"Pass",'Test Cases'!$G$5:$G$82,1) | D4: =COUNTIFS('Test Cases'!$I$5:$I$82,"Fail",'Test Cases'!$G$5:$G$82,1) | E4: =COUNTIFS('Test Cases'!$I$5:$I$82,"Blocked",'Test Cases'!$G$5:$G$82,1) | F4: =COUNTIFS('Test Cases'!$I$5:$I$82,"Not run",'Test Cases'!$G$5:$G$82,1) | G4: =C4+D4 | H4: =IFERROR(C4/G4,0)
A5: Sprint 2 | B5: =COUNTIFS('Test Cases'!$A$5:$A$82,"<>",'Test Cases'!$G$5:$G$82,2) | C5: =COUNTIFS('Test Cases'!$I$5:$I$82,"Pass",'Test Cases'!$G$5:$G$82,2) | D5: =COUNTIFS('Test Cases'!$I$5:$I$82,"Fail",'Test Cases'!$G$5:$G$82,2) | E5: =COUNTIFS('Test Cases'!$I$5:$I$82,"Blocked",'Test Cases'!$G$5:$G$82,2) | F5: =COUNTIFS('Test Cases'!$I$5:$I$82,"Not run",'Test Cases'!$G$5:$G$82,2) | G5: =C5+D5 | H5: =IFERROR(C5/G5,0)
A6: Total | B6: =COUNTA('Test Cases'!$A$5:$A$82) | C6: =COUNTIFS('Test Cases'!$I$5:$I$82,"Pass") | D6: =COUNTIFS('Test Cases'!$I$5:$I$82,"Fail") | E6: =COUNTIFS('Test Cases'!$I$5:$I$82,"Blocked") | F6: =COUNTIFS('Test Cases'!$I$5:$I$82,"Not run") | G6: =C6+D6 | H6: =IFERROR(C6/G6,0)
A8: Executed = Pass + Fail (Blocked and Not run are not counted as executed). Pass % = Pass / Executed.
A10: By priority
A11: Priority | B11: Planned | C11: Pass | D11: Fail
A12: High | B12: =COUNTIFS('Test Cases'!$H$5:$H$82,A12) | C12: =COUNTIFS('Test Cases'!$H$5:$H$82,A12,'Test Cases'!$I$5:$I$82,"Pass") | D12: =COUNTIFS('Test Cases'!$H$5:$H$82,A12,'Test Cases'!$I$5:$I$82,"Fail")
A13: Medium | B13: =COUNTIFS('Test Cases'!$H$5:$H$82,A13) | C13: =COUNTIFS('Test Cases'!$H$5:$H$82,A13,'Test Cases'!$I$5:$I$82,"Pass") | D13: =COUNTIFS('Test Cases'!$H$5:$H$82,A13,'Test Cases'!$I$5:$I$82,"Fail")
A14: Low | B14: =COUNTIFS('Test Cases'!$H$5:$H$82,A14) | C14: =COUNTIFS('Test Cases'!$H$5:$H$82,A14,'Test Cases'!$I$5:$I$82,"Pass") | D14: =COUNTIFS('Test Cases'!$H$5:$H$82,A14,'Test Cases'!$I$5:$I$82,"Fail")
